Workbook

Sheet کاتالوگ مبلمان
L1: تاریخ لیست قیمت | M1: 1405/02/01
D17: لیست قیمت مبلمان حذف از تولید
H20: (1405/02/01)
D41: فهرست
D42: دسته محصولات | I42: صفحه
D44: مبل آکومه (با پارچه) | I44: 4
D46: مبل آکومه (بدون پارچه) | I46: 5
D48: مبل ساپلی (با پارچه) | I48: 6
D50: مبل ساپلی (بدون پارچه) | I50: 6
D52: مبل ساپن (با پارچه) | I52: 7
D54: مبل ساپن (بدون پارچه) | I54: 8
D56: مبل سیپو (با پارچه) | I56: 9
D58: مبل سیپو (بدون پارچه) | I58: 10
D60: مبل کاتیوو (با پارچه) | I60: 11
D62: مبل کاتیوو (بدون پارچه) | I62: 12
D64: مبل چستر (با پارچه) | I64: 13
D66: مبل چستر (بدون پارچه) | I66: 13
D68: مبل ماپا (با پارچه) | I68: 14
D70: مبل ماپا (بدون پارچه) | I70: 15
... D84: مبل پیناس (با پارچه ) | I84: 22
D86: فهرست
D87: دسته محصولات | I87: صفحه
D89: مبل پیناس (بدون پارچه) | I89: 23
D91: مبل داگلاس (با پارچه) | I91: 24
D93: مبل داگلاس (بدون پارچه) | I93: 25
D95: مبل میپل (با پارچه) | I95: 26
D97: مبل میپل (بدون پارچه) | I97: 27
D99: مبل تیلیا (با پارچه) | I99: 28
D101: مبل تیلیا (بدون پارچه) | I101: 29
D103: مبل سالیکس (با پارچه) | I103: 30
D105: مبل سالیکس (بدون پارچه) | I105: 31
D107: مبل بالزا (با پارچه) | I107: 32
D109: مبل بالزا (بدون پارچه) | I109: 32
D111: غذاخوری آکومه (با پارچه) | I111: 33
... D131: غذاخوری نوئل (بدون پارچه) | I131: 39
D133: فهرست
D134: دسته محصولات | I134: صفحه
D136: غذاخوری میپل (با پارچه) | I136: 40
D138: غذاخوری میپل (بدون پارچه) | I138: 41
D140: سرویس خواب ساپلی | I140: 42
...

Sheet کاتالوگ کالای خواب
R1: تاریخ لیست قیمت | S1: 1405/02/01
C22: لیست قیمت کالای خواب حذف از تولید
M26: (1405/02/01)
D56: فهرست
D57: دسته محصولات | O57: صفحه
D59: بالش | O59: 2
D61: سرویس روتختی | O61: 3-4
D63: سرویس ملحفه | O63: 5
D65: لحاف | O65: 6
D67: پتو | O67: 7
D69: تشک آریل | O69: 8
E94: بالش | N94: =$S$1 -> 1405/02/01
D95: ردیف | E95: کد کالا | I95: شرح | N95: قیمت (ریال)
D97: 1 | E97: =INDEX(' کالای خواب حذف از لیست اصلی'!C:C,MATCH(P97,' کالای خواب حذف از لیست اصلی'!P:P,0)) -> #N/A | I97: =INDEX(' کالای خواب حذف از لیست اصلی'!D:D,MATCH(P97,' کالای خواب حذف از لیست اصلی'!P:P,0)) -> #N/A | N97: =INDEX(' کالای خواب حذف از لیست اصلی'!F:F,MATCH(P97,' کالای خواب حذف از لیست اصلی'!P:P,0)) -> #N/A | P97: 1
D98: 2 | E98: =INDEX(' کالای خواب حذف از لیست اصلی'!C:C,MATCH(P98,' کالای خواب حذف از لیست اصلی'!P:P,0)) -> 9900120004 | I98: =INDEX(' کالای خواب حذف از لیست اصلی'!D:D,MATCH(P98,' کالای خواب حذف از لیست اصلی'!P:P,0)) -> بالش آتریپلکس / پلوم (90%پر) | N98: =INDEX(' کالای خواب حذف از لیست اصلی'!F:F,MATCH(P98,' کالای خواب حذف از لیست اصلی'!P:P,0)) -> 90000000 | P98: 2
D99: 3 | E99: =INDEX(' کالای خواب حذف از لیست اصلی'!C:C,MATCH(P99,' کالای خواب حذف از لیست اصلی'!P:P,0)) -> 9900120005 | I99: =INDEX(' کالای خواب حذف از لیست اصلی'!D:D,MATCH(P99,' کالای خواب حذف از لیست اصلی'!P:P,0)) -> بالش آتریپلکس / پاکت پیلو | N99: =INDEX(' کالای خواب حذف از لیست اصلی'!F:F,MATCH(P99,' کالای خواب حذف از لیست اصلی'!P:P,0)) -> 101000000 | P99: 3
D100: 4 | E100: =INDEX(' کالای خواب حذف از لیست اصلی'!C:C,MATCH(P100,' کالای خواب حذف از لیست اصلی'!P:P,0)) -> 9900120006 | I100: =INDEX(' کالای خواب حذف از لیست اصلی'!D:D,MATCH(P100,' کالای خواب حذف از لیست اصلی'!P:P,0)) -> بالش آتریپلکس / بامبو | N100: =INDEX(' کالای خواب حذف از لیست اصلی'!F:F,MATCH(P100,' کالای خواب حذف از لیست اصلی'!P:P,0)) -> 78000000 | P100: 4
D101: 5 | E101: =INDEX(' کالای خواب حذف از لیست اصلی'!C:C,MATCH(P101,' کالای خواب حذف از لیست اصلی'!P:P,0)) -> 9900120007 | I101: =INDEX(' کالای خواب حذف از لیست اصلی'!D:D,MATCH(P101,' کالای خواب حذف از لیست اصلی'!P:P,0)) -> بالش آتریپلکس / آلوئه ورا | N101: =INDEX(' کالای خواب حذف از لیست اصلی'!F:F,MATCH(P101,' کالای خواب حذف از لیست اصلی'!P:P,0)) -> 67000000 | P101: 5
D102: 6 | E102: =INDEX(' کالای خواب حذف از لیست اصلی'!C:C,MATCH(P102,' کالای خواب حذف از لیست اصلی'!P:P,0)) -> 9900120008 | I102: =INDEX(' کالای خواب حذف از لیست اصلی'!D:D,MATCH(P102,' کالای خواب حذف از لیست اصلی'!P:P,0)) -> بالش آتریپلکس / میکرو نیدل | N102: =INDEX(' کالای خواب حذف از لیست اصلی'!F:F,MATCH(P102,' کالای خواب حذف از لیست اصلی'!P:P,0)) -> 76000000 | P102: 6
D103: 7 | E103: =INDEX(' کالای خواب حذف از لیست اصلی'!C:C,MATCH(P103,' کالای خواب حذف از لیست اصلی'!P:P,0)) -> 9900120009 | I103: =INDEX(' کالای خواب حذف از لیست اصلی'!D:D,MATCH(P103,' کالای خواب حذف از لیست اصلی'!P:P,0)) -> بالش آتریپلکس / آل سیزنس | N103: =INDEX(' کالای خواب حذف از لیست اصلی'!F:F,MATCH(P103,' کالای خواب حذف از لیست اصلی'!P:P,0)) -> 76000000 | P103: 7
D104: 8 | E104: =INDEX(' کالای خواب حذف از لیست اصلی'!C:C,MATCH(P104,' کالای خواب حذف از لیست اصلی'!P:P,0)) -> 9900120010 | I104: =INDEX(' کالای خواب حذف از لیست اصلی'!D:D,MATCH(P104,' کالای خواب حذف از لیست اصلی'!P:P,0)) -> بالش آتریپلکس / نچرال | N104: =INDEX(' کالای خواب حذف از لیست اصلی'!F:F,MATCH(P104,' کالای خواب حذف از لیست اصلی'!P:P,0)) -> 76000000 | P104: 8
D105: 9 | E105: =INDEX(' کالای خواب حذف از لیست اصلی'!C:C,MATCH(P105,' کالای خواب حذف از لیست اصلی'!P:P,0)) -> 9900120011 | I105: =INDEX(' کالای خواب حذف از لیست اصلی'!D:D,MATCH(P105,' کالای خواب حذف از لیست اصلی'!P:P,0)) -> بالش آتریپلکس / هایپرکلاس | N105: =INDEX(' کالای خواب حذف از لیست اصلی'!F:F,MATCH(P105,' کالای خواب حذف از لیست اصلی'!P:P,0)) -> 88000000 | P105: 9
D106: 10 | E106: =INDEX(' کالای خواب حذف از لیست اصلی'!C:C,MATCH(P106,' کالای خواب حذف از لیست اصلی'!P:P,0)) -> 9900120012 | I106: =INDEX(' کالای خواب حذف از لیست اصلی'!D:D,MATCH(P106,' کالای خواب حذف از لیست اصلی'!P:P,0)) -> بالش آتریپلکس / فرش کول | N106: =INDEX(' کالای خواب حذف از لیست اصلی'!F:F,MATCH(P106,' کالای خواب حذف از لیست اصلی'!P:P,0)) -> 108000000 | P106: 10
D107: 11 | E107: =INDEX(' کالای خواب حذف از لیست اصلی'!C:C,MATCH(P107,' کالای خواب حذف از لیست اصلی'!P:P,0)) -> 9900120023 | I107: =INDEX(' کالای خواب حذف از لیست اصلی'!D:D,MATCH(P107,' کالای خواب حذف از لیست اصلی'!P:P,0)) -> بالش مون سیلک | N107: =INDEX(' کالای خواب حذف از لیست اصلی'!F:F,MATCH(P107,' کالای خواب حذف از لیست اصلی'!P:P,0)) -> 173000000 | P107: 11
D108: 12 | E108: =INDEX(' کالای خواب حذف از لیست اصلی'!C:C,MATCH(P108,' کالای خواب حذف از لیست اصلی'!P:P,0)) -> 9900120024 | I108: =INDEX(' کالای خواب حذف از لیست اصلی'!D:D,MATCH(P108,' کالای خواب حذف از لیست اصلی'!P:P,0)) -> بالش توین رست | N108: =INDEX(' کالای خواب حذف از لیست اصلی'!F:F,MATCH(P108,' کالای خواب حذف از لیست اصلی'!P:P,0)) -> 106000000 | P108: 12
D109: 13 | E109: =INDEX(' کالای خواب حذف از لیست اصلی'!C:C,MATCH(P109,' کالای خواب حذف از لیست اصلی'!P:P,0)) -> 9900120025 | I109: =INDEX(' کالای خواب حذف از لیست اصلی'!D:D,MATCH(P109,' کالای خواب حذف از لیست اصلی'!P:P,0)) -> بالش طبی مموری ترکیبی | N109: =INDEX(' کالای خواب حذف از لیست اصلی'!F:F,MATCH(P109,' کالای خواب حذف از لیست اصلی'!P:P,0)) -> 164000000 | P109: 13
O112: 2
E115: سرویس روتختی | N115: =$S$1 -> 1405/02/01
D116: ردیف | E116: کد کالا | I116: شرح | N116: قیمت (ریال)
D118: 1 | E118: =INDEX(' کالای خواب حذف از لیست اصلی'!C:C,MATCH(P118,' کالای خواب حذف از لیست اصلی'!P:P,0)) -> 9900130005 | I118: =INDEX(' کالای خواب حذف از لیست اصلی'!D:D,MATCH(P118,' کالای خواب حذف از لیست اصلی'!P:P,0)) -> سرویس روتختی دونفره سه تکه فریزیا / زغالی | N118: =INDEX(' کالای خواب حذف از لیست اصلی'!F:F,MATCH(P118,' کالای خواب حذف از لیست اصلی'!P:P,0)) -> 336000000 | P118: 14
D119: 2 | E119: =INDEX(' کالای خواب حذف از لیست اصلی'!C:C,MATCH(P119,' کالای خواب حذف از لیست اصلی'!P:P,0)) -> 9900130006 | I119: =INDEX(' کالای خواب حذف از لیست اصلی'!D:D,MATCH(P119,' کالای خواب حذف از لیست اصلی'!P:P,0)) -> سرویس روتختی دونفره سه تکه فریزیا / مسی | N119: =INDEX(' کالای خواب حذف از لیست اصلی'!F:F,MATCH(P119,' کالای خواب حذف از لیست اصلی'!P:P,0)) -> 336000000 | P119: 15
D120: 3 | E120: =INDEX(' کالای خواب حذف از لیست اصلی'!C:C,MATCH(P120,' کالای خواب حذف از لیست اصلی'!P:P,0)) -> 9900130007 | I120: =INDEX(' کالای خواب حذف از لیست اصلی'!D:D,MATCH(P120,' کالای خواب حذف از لیست اصلی'!P:P,0)) -> سرویس روتختی دونفره سه تکه فریزیا /آبی تیره | N120: =INDEX(' کالای خواب حذف از لیست اصلی'!F:F,MATCH(P120,' کالای خواب حذف از لیست اصلی'!P:P,0)) -> 336000000 | P120: 16
D121: 4 | E121: =INDEX(' کالای خواب حذف از لیست اصلی'!C:C,MATCH(P121,' کالای خواب حذف از لیست اصلی'!P:P,0)) -> 9900130008 | I121: =INDEX(' کالای خواب حذف از لیست اصلی'!D:D,MATCH(P121,' کالای خواب حذف از لیست اصلی'!P:P,0)) -> سرویس روتختی دونفره سه تکه فریزیا / خاکستری | N121: =INDEX(' کالای خواب حذف از لیست اصلی'!F:F,MATCH(P121,' کالای خواب حذف از لیست اصلی'!P:P,0)) -> 336000000 | P121: 17
D122: 5 | E122: =INDEX(' کالای خواب حذف از لیست اصلی'!C:C,MATCH(P122,' کالای خواب حذف از لیست اصلی'!P:P,0)) -> 9900130009 | I122: =INDEX(' کالای خواب حذف از لیست اصلی'!D:D,MATCH(P122,' کالای خواب حذف از لیست اصلی'!P:P,0)) -> سرویس روتختی یک نفره دو تکه فریزیا / زغالی | N122: =INDEX(' کالای خواب حذف از لیست اصلی'!F:F,MATCH(P122,' کالای خواب حذف از لیست اصلی'!P:P,0)) -> 268000000 | P122: 18
D123: 6 | E123: =INDEX(' کالای خواب حذف از لیست اصلی'!C:C,MATCH(P123,' کالای خواب حذف از لیست اصلی'!P:P,0)) -> 9900130010 | I123: =INDEX(' کالای خواب حذف از لیست اصلی'!D:D,MATCH(P123,' کالای خواب حذف از لیست اصلی'!P:P,0)) -> سرویس روتختی یک نفره دو تکه فریزیا / مسی | N123: =INDEX(' کالای خواب حذف از لیست اصلی'!F:F,MATCH(P123,' کالای خواب حذف از لیست اصلی'!P:P,0)) -> 268000000 | P123: 19
D124: 7 | E124: =INDEX(' کالای خواب حذف از لیست اصلی'!C:C,MATCH(P124,' کالای خواب حذف از لیست اصلی'!P:P,0)) -> 9900130011 | I124: =INDEX(' کالای خواب حذف از لیست اصلی'!D:D,MATCH(P124,' کالای خواب حذف از لیست اصلی'!P:P,0)) -> سرویس روتختی یک نفره دو تکه فریزیا / آبی تیره | N124: =INDEX(' کالای خواب حذف از لیست اصلی'!F:F,MATCH(P124,' کالای خواب حذف از لیست اصلی'!P:P,0)) -> 268000000 | P124: 20
D125: 8 | E125: =INDEX(' کالای خواب حذف از لیست اصلی'!C:C,MATCH(P125,' کالای خواب حذف از لیست اصلی'!P:P,0)) -> 9900130012 | I125: =INDEX(' کالای خواب حذف از لیست اصلی'!D:D,MATCH(P125,' کالای خواب حذف از لیست اصلی'!P:P,0)) -> سرویس روتختی یک نفره دو تکه فریزیا / خاکستری | N125: =INDEX(' کالای خواب حذف از لیست اصلی'!F:F,MATCH(P125,' کالای خواب حذف از لیست اصلی'!P:P,0)) -> 268000000 | P125: 21
D126: 9 | E126: =INDEX(' کالای خواب حذف از لیست اصلی'!C:C,MATCH(P126,' کالای خواب حذف از لیست اصلی'!P:P,0)) -> 9900130022 | I126: =INDEX(' کالای خواب حذف از لیست اصلی'!D:D,MATCH(P126,' کالای خواب حذف از لیست اصلی'!P:P,0)) -> سرویس روتختی دو نفره یازده تکه ماری گلد 22 | N126: =INDEX(' کالای خواب حذف از لیست اصلی'!F:F,MATCH(P126,' کالای خواب حذف از لیست اصلی'!P:P,0)) -> 747000000 | P126: 22
D127: 10 | E127: =INDEX(' کالای خواب حذف از لیست اصلی'!C:C,MATCH(P127,' کالای خواب حذف از لیست اصلی'!P:P,0)) -> 9900130025 | I127: =INDEX(' کالای خواب حذف از لیست اصلی'!D:D,MATCH(P127,' کالای خواب حذف از لیست اصلی'!P:P,0)) -> سرویس روتختی و کاور کینگ ده تکه دکوماریا 25 | N127: =INDEX(' کالای خواب حذف از لیست اصلی'!F:F,MATCH(P127,' کالای خواب حذف از لیست اصلی'!P:P,0)) -> 995000000 | P127: 23
D128: 11 | E128: =INDEX(' کالای خواب حذف از لیست اصلی'!C:C,MATCH(P128,' کالای خواب حذف از لیست اصلی'!P:P,0)) -> 9900130030 | I128: =INDEX(' کالای خواب حذف از لیست اصلی'!D:D,MATCH(P128,' کالای خواب حذف از لیست اصلی'!P:P,0)) -> سرویس روتختی دو نفره سه تکه کاتالیا 30 | N128: =INDEX(' کالای خواب حذف از لیست اصلی'!F:F,MATCH(P128,' کالای خواب حذف از لیست اصلی'!P:P,0)) -> 137000000 | P128: 24
...

Sheet حذف از تولید و لیست اصلی
A1: محصولات حذف شده از سری تولید و لیست قیمت | E1: تاریخ:1405/06/14
A2: مبل آکومه (با پارچه)
A3: ردیف | B3: کد کالا | C3: شرح | D3: قیمت (ریال) | E3: قیمت جدید (ریال) | F3: کد مجازی | I3: کد کاتالوگ
A4: 1 | B4: 2110010000 | C4: مبل هفت‌نفره آکومه (یک عدد سه‌نفره + یک عدد دونفره + دو عدد یک‌نفره) | D4: 4831700000 | E4: =E5+E6+E7+E7 -> 5751000000 | I4: 1
A5: =A4+1 -> 2 | B5: 2110010300 | C5: کاناپه سه‌نفره آکومه (4 عدد کوسن) | D5: 1584600000 | E5: =E16+(10*$H$12) -> 1886000000 | F5: =LEFT(B5,8)&"00" -> 2110010300 | I5: 2
A6: =A5+1 -> 3 | B6: 2110010200 | C6: کاناپه دونفره آکومه (4 عدد کوسن) | D6: 1198300000 | E6: =E17+(8*$H$12) -> 1425000000 | F6: =LEFT(B6,8)&"00" -> 2110010200 | I6: 3
A7: =A6+1 -> 4 | B7: 2110010100 | C7: مبل یک‌نفره آکومه (1 عدد کوسن) | D7: 1024400000 | E7: =E18+(6*$H$12) -> 1220000000 | F7: =LEFT(B7,8)&"00" -> 2110010100 | I7: 4
A8: =A7+1 -> 5 | B8: - | C8: متراژ پارچه هفت‌نفره (فریم 16 متر + تشک 8.5 متر + کوسن 5.5 متر) | D8: 30 متر | E8: 30 متر | I8: 5
A9: =A8+1 -> 6 | B9: - | C9: متراژ پارچه سه‌نفره (فریم 5 متر + تشک 3 متر + کوسن 2 متر) | D9: 10 متر | E9: 10 متر | I9: 6
A10: =A9+1 -> 7 | B10: - | C10: متراژ پارچه دونفره (فریم 4.5 متر + تشک 2 متر + کوسن 1.5 متر) | D10: 8 متر | E10: 8 متر | I10: 7
A11: =A10+1 -> 8 | B11: - | C11: متراژ پارچه یک‌نفره (فریم بیرون، داخل و تشک از یک پارچه 5 متر + کوسن 1 متر) | D11: 6 متر | E11: 6 متر | I11: 8
A12: =A11+1 -> 9 | B12: - | C12: متراژ پارچه یک‌نفره (فریم بیرون 2 متر + فریم داخل و تشک 3.5 متر + کوسن 1 متر) | D12: 6.5 متر | E12: 6.5 متر | G12: پارچه | H12: 20000000 | I12: 9
A13: مبل آکومه (بدون پارچه) | G13: نرخ 1 | H13: 0.2
A14: ردیف | B14: کد کالا | C14: شرح کالا | D14: قیمت (ریال) | E14: قیمت جدید (ریال) | F14: کد مجازی | G14: نرخ 2 | H14: 0
A15: 1 | B15: 2110010000 | C15: مبل هفت‌نفره آکومه (یک عدد سه‌نفره + یک عدد دونفره + دو عدد یک‌نفره) | D15: 4291700000 | E15: =E16+E17+E18+E18 -> 5151000000 | I15: 10
A16: =A15+1 -> 2 | B16: 2110010300 | C16: کاناپه سه‌نفره آکومه (4 عدد کوسن) | D16: 1404600000 | E16: =ROUND(((100%+$H$13)*D16)*(100%+$H$14),-6) -> 1686000000 | F16: =LEFT(B16,8)&"00" -> 2110010300 | I16: 11
A17: =A16+1 -> 3 | B17: 2110010200 | C17: کاناپه دونفره آکومه (4 عدد کوسن) | D17: 1054300000 | E17: =ROUND(((100%+$H$13)*D17)*(100%+$H$14),-6) -> 1265000000 | F17: =LEFT(B17,8)&"00" -> 2110010200 | I17: 12
A18: =A17+1 -> 4 | B18: 2110010100 | C18: مبل یک‌نفره آکومه (1 عدد کوسن) | D18: 916400000 | E18: =ROUND(((100%+$H$13)*D18)*(100%+$H$14),-6) -> 1100000000 | F18: =LEFT(B18,8)&"00" -> 2110010100 | I18: 13
A19: =A18+1 -> 5 | B19: - | C19: متراژ پارچه هفت‌نفره (فریم 16 متر + تشک 8.5 متر + کوسن 5.5 متر) | D19: 30 متر | E19: 30 متر | I19: 14
A20: =A19+1 -> 6 | B20: - | C20: متراژ پارچه سه‌نفره (فریم 5 متر + تشک 3 متر + کوسن 2 متر) | D20: 10 متر | E20: 10 متر | I20: 15
A21: =A20+1 -> 7 | B21: - | C21: متراژ پارچه دونفره (فریم 4.5 متر + تشک 2 متر + کوسن 1.5 متر) | D21: 8 متر | E21: 8 متر | I21: 16
A22: =A21+1 -> 8 | B22: - | C22: متراژ پارچه یک‌نفره (فریم بیرون، داخل و تشک از یک پارچه 5 متر + کوسن 1 متر) | D22: 6 متر | E22: 6 متر | I22: 17
A23: =A22+1 -> 9 | B23: - | C23: متراژ پارچه یک‌نفره (فریم بیرون 2 متر + فریم داخل و تشک 3.5 متر + کوسن 1 متر) | D23: 6.5 متر | E23: 6.5 متر | I23: 18
A24: مبلمان (با پارچه)
A25: ردیف | B25: کد کالا | C25: شرح | D25: قیمت (ریال) | E25: قیمت جدید (ریال) | F25: کد مجازی
A26: 1 | B26: 2160010300 | C26: پاف ساپلی | D26: 389000000 | E26: =E30+(2.5*$H$26) -> 463000000 | F26: =LEFT(B26,8)&"00" -> 2160010300 | G26: پارچه | H26: 20000000 | I26: 19
A27: 2 | B27: - | C27: متراژ پارچه پاف | D27: 2/5متر | E27: 2/5متر | G27: نرخ 1 | H27: 0.2 | I27: 20
A28: مبلمان ( بدون پارچه) | G28: نرخ 2 | H28: 0
A29: ردیف | B29: کد کالا | C29: شرح | D29: قیمت (ریال) | E29: قیمت جدید (ریال) | F29: کد مجازی
A30: 1 | B30: 2160010300 | C30: پاف ساپلی | D30: 344000000 | E30: =ROUND(((100%+$H$27)*D30)*(100%+$H$28),-6) -> 413000000 | F30: =LEFT(B30,8)&"00" -> 2160010300 | I30: 21
A31: 2 | B31: - | C31: متراژ پارچه پاف | D31: 2/5متر | E31: 2/5متر | I31: 22
A32: مبل ساپن (با پارچه)
A33: ردیف | B33: کد کالا | C33: شرح | D33: قیمت (ریال) | E33: قیمت جدید (ریال) | F33: کد مجازی
A34: 1 | B34: 2110030300 | C34: کاناپه سه نفره ساپن ( 5 عددکوسن ) | D34: 951400000 | E34: =E44+(11.5*$H$41) -> 1123000000 | F34: =LEFT(B34,8)&"00" -> 2110030300 | I34: 23
A35: =A34+1 -> 2 | B35: 2110030200 | C35: کاناپه دو نفره ساپن ( 4 عدد کوسن ) | D35: 727400000 | E35: =E45+(9.5*$H$41) -> 858000000 | F35: =LEFT(B35,8)&"00" -> 2110030200 | I35: 24
A36: =A35+1 -> 3 | B36: 2110030100 | C36: مبل یک نفره ساپن ( 1 عدد کوسن ) | D36: 429600000 | E36: =E46+(3.8*$H$41) -> 509000000 | F36: =LEFT(B36,8)&"00" -> 2110030100 | I36: 25
A37: =A36+1 -> 4 | B37: 2110030500 | C37: میز جلو مبلی ساپن | D37: 480000000 | E37: =ROUND(((100%+$H$42)*D37)*(100%+$H$43),-6) -> 576000000 | F37: =LEFT(B37,8)&"00" -> 2110030500 | I37: 26
A38: =A37+1 -> 5 | B38: 2110030600 | C38: میز کنار مبلی ساپن | D38: 366700000 | E38: =ROUND(((100%+$H$42)*D38)*(100%+$H$43),-6) -> 440000000 | F38: =LEFT(B38,8)&"00" -> 2110030600 | I38: 27
A39: =A38+1 -> 6 | C39: متراژ پارچه سه نفره ( فریم 6/5 متر + تشک 3 متر + کوسن 2 متر) | D39: 11/5متر | E39: 11/5متر | I39: 28
A40: =A39+1 -> 7 | C40: متراژ پارچه دو نفره ( فریم 5/5 متر + تشک 2 متر + کوسن 2متر ) | D40: 9/5متر | E40: 9/5متر | I40: 29
...

Sheet اکسسوری حذف از لیست اصلی
A1: لیست قیمت اکسسوری اردیبهشت ماه 1405
A3: ردیف | B3: دسته بندی | C3: کد کالا | D3: شرح کالا | E3: طول (سانتی متر) | F3: عرض (سانتی متر) | G3: ارتفاع (سانتی متر) | H3: وزن (کیلوگرم) | I3: قیمت (ریال) | J3: قیمت جدید
A4: 1 | B4: آباژور رومیزی | C4: 9901010001 | D4: آباژور رومیزی چوبی طوسی TL-W001 | E4: 43 | F4: 43 | G4: 69 | I4: 103700000 | J4: =ROUND(((100%+$M$7)*Table30[[#This Row],[قیمت (ریال)]])*(100%+$M$8),-6) -> 124000000 | T4: 1
A5: 2 | B5: آباژور رومیزی | C5: 9901010002 | D5: آباژور رومیزی چوبی مشکی طلایی TL-W002 | E5: 43 | F5: 43 | G5: 70 | I5: 103700000 | J5: =ROUND(((100%+$M$7)*Table30[[#This Row],[قیمت (ریال)]])*(100%+$M$8),-6) -> 124000000 | T5: 2
A6: 3 | B6: آباژور رومیزی | C6: 9901010003 | D6: آباژور رومیزی چوبی مشکیTL-W003 | E6: 43 | F6: 43 | G6: 69 | I6: 103700000 | J6: =ROUND(((100%+$M$7)*Table30[[#This Row],[قیمت (ریال)]])*(100%+$M$8),-6) -> 124000000 | T6: 3
A7: 4 | B7: آباژور رومیزی | C7: 9901010004 | D7: آباژور رومیزی چوبی کرم TL-W004 | E7: 43 | F7: 43 | G7: 69 | I7: 103700000 | J7: =ROUND(((100%+$M$7)*Table30[[#This Row],[قیمت (ریال)]])*(100%+$M$8),-6) -> 124000000 | L7: درصد افزایش 1 | M7: 0.2 | T7: 4
A8: 5 | B8: آباژور رومیزی | C8: 9901010005 | D8: آباژور رومیزی چوبی طوسی TL-W005 | E8: 43 | F8: 43 | G8: 64 | I8: 103700000 | J8: =ROUND(((100%+$M$7)*Table30[[#This Row],[قیمت (ریال)]])*(100%+$M$8),-6) -> 124000000 | L8: درصد افزایش 2 | M8: 0 | T8: 5
A9: 6 | B9: آباژور رومیزی | C9: 9901010006 | D9: آباژور رومیزی چوبی قهوه ای TL-W006 | E9: 43 | F9: 43 | G9: 64 | I9: 103700000 | J9: =ROUND(((100%+$M$7)*Table30[[#This Row],[قیمت (ریال)]])*(100%+$M$8),-6) -> 124000000 | T9: 6
A10: 7 | B10: آباژور رومیزی | C10: 9901010007 | D10: آباژور رومیزی چوبی مشکی TL-W007 | E10: 43 | F10: 43 | G10: 69 | I10: 103700000 | J10: =ROUND(((100%+$M$7)*Table30[[#This Row],[قیمت (ریال)]])*(100%+$M$8),-6) -> 124000000 | T10: 7
A11: 8 | B11: آباژور رومیزی | C11: 9901010008 | D11: آباژور رومیزی چوبی سفید TL-W008 | E11: 43 | F11: 43 | G11: 69 | I11: 103700000 | J11: =ROUND(((100%+$M$7)*Table30[[#This Row],[قیمت (ریال)]])*(100%+$M$8),-6) -> 124000000 | T11: 8
A12: 9 | B12: آباژور رومیزی | C12: 9901010009 | D12: آباژور رومیزی چوبی مشکی TL-W009 | E12: 43 | F12: 43 | G12: 65 | I12: 103700000 | J12: =ROUND(((100%+$M$7)*Table30[[#This Row],[قیمت (ریال)]])*(100%+$M$8),-6) -> 124000000 | T12: 9
A13: 10 | B13: آباژور رومیزی | C13: 9901010010 | D13: آباژور رومیزی سنگی TL-S010 | E13: 22 | F13: 22 | G13: 63 | I13: 82600000 | J13: =ROUND(((100%+$M$7)*Table30[[#This Row],[قیمت (ریال)]])*(100%+$M$8),-6) -> 99000000 | T13: 10
A14: 11 | B14: آباژور رومیزی | C14: 9901010011 | D14: آباژور رومیزی چوبی کرم طلایی TL-W011 | E14: 35 | F14: 35 | G14: 64 | I14: 103700000 | J14: =ROUND(((100%+$M$7)*Table30[[#This Row],[قیمت (ریال)]])*(100%+$M$8),-6) -> 124000000 | T14: 11
A15: 12 | B15: آباژور رومیزی | C15: 9901010012 | D15: آباژور رومیزی چوبی مارون TL-W012 | E15: 43 | F15: 43 | G15: 70 | I15: 103700000 | J15: =ROUND(((100%+$M$7)*Table30[[#This Row],[قیمت (ریال)]])*(100%+$M$8),-6) -> 124000000 | T15: 12
A16: 13 | B16: آباژور رومیزی | C16: 9901010013 | D16: آباژور رومیزی چوبی گردوییTL-W013 | E16: 43 | F16: 43 | G16: 70 | I16: 103700000 | J16: =ROUND(((100%+$M$7)*Table30[[#This Row],[قیمت (ریال)]])*(100%+$M$8),-6) -> 124000000 | T16: 13
A17: 14 | B17: آباژور رومیزی | C17: 9901010014 | D17: آباژور رومیزی شیشه ای مشکی TL-G014 | E17: 35 | F17: 35 | G17: 46 | I17: 108000000 | J17: =ROUND(((100%+$M$7)*Table30[[#This Row],[قیمت (ریال)]])*(100%+$M$8),-6) -> 130000000 | T17: 14
A18: 15 | B18: آباژور رومیزی | C18: 9901010015 | D18: آباژور رومیزی شیشه ای مشکی TL-G015 | E18: 35 | F18: 35 | G18: 54 | I18: 108000000 | J18: =ROUND(((100%+$M$7)*Table30[[#This Row],[قیمت (ریال)]])*(100%+$M$8),-6) -> 130000000 | T18: 15
A19: 16 | B19: آباژور رومیزی | C19: 9901010016 | D19: آباژور رومیزی سنگی سفید TL-S016 | E19: 35*35 | I19: 135800000 | J19: =ROUND(((100%+$M$7)*Table30[[#This Row],[قیمت (ریال)]])*(100%+$M$8),-6) -> 163000000 | T19: 16
A20: 17 | B20: آباژور رومیزی | C20: 9901010018 | D20: آباژور رومیزی سرامیکی کرم TL-CR018 | E20: 30*30 | I20: 94300000 | J20: =ROUND(((100%+$M$7)*Table30[[#This Row],[قیمت (ریال)]])*(100%+$M$8),-6) -> 113000000 | T20: 17
A21: 18 | B21: آباژور رومیزی | C21: 9901010019 | D21: آباژور رومیزی سرامیکی کرم TL-CR019 | E21: 30 | F21: 30 | G21: 59 | I21: 72000000 | J21: =ROUND(((100%+$M$7)*Table30[[#This Row],[قیمت (ریال)]])*(100%+$M$8),-6) -> 86000000 | T21: 18
A22: 19 | B22: آباژور رومیزی | C22: 9901010020 | D22: آباژور رومیزی استیل طلایی TL-ST020 | E22: 35 | F22: 35 | G22: 65 | I22: 114000000 | J22: =ROUND(((100%+$M$7)*Table30[[#This Row],[قیمت (ریال)]])*(100%+$M$8),-6) -> 137000000 | T22: 19
A23: 20 | B23: آباژور رومیزی | C23: 9901010021 | D23: آباژور رومیزی استیل نقره ای TL-ST021 | E23: 45 | F23: 45 | G23: 85 | I23: 82600000 | J23: =ROUND(((100%+$M$7)*Table30[[#This Row],[قیمت (ریال)]])*(100%+$M$8),-6) -> 99000000 | T23: 20
A24: 21 | B24: آباژور رومیزی | C24: 9901010022 | D24: آباژور رومیزی سفالی کرم TL-C022 | E24: 45 | F24: 45 | G24: 55 | I24: 137600000 | J24: =ROUND(((100%+$M$7)*Table30[[#This Row],[قیمت (ریال)]])*(100%+$M$8),-6) -> 165000000 | T24: 21
A25: 22 | B25: آباژور رومیزی | C25: 9901010023 | D25: آباژور رومیزی سفالی خاکی TL-C023 | E25: 45 | F25: 45 | G25: 50 | I25: 137600000 | J25: =ROUND(((100%+$M$7)*Table30[[#This Row],[قیمت (ریال)]])*(100%+$M$8),-6) -> 165000000 | T25: 22
A26: 23 | B26: آباژور رومیزی | C26: 9901010024 | D26: آباژور رومیزی سفالی فیلی TL-C024 | E26: 45 | F26: 45 | G26: 48 | I26: 105200000 | J26: =ROUND(((100%+$M$7)*Table30[[#This Row],[قیمت (ریال)]])*(100%+$M$8),-6) -> 126000000 | T26: 23
A27: 24 | B27: آباژور رومیزی | C27: 9901010025 | D27: آباژور رومیزی سفالی طوسی TL-C025 | E27: 45 | F27: 45 | G27: 48 | I27: 105200000 | J27: =ROUND(((100%+$M$7)*Table30[[#This Row],[قیمت (ریال)]])*(100%+$M$8),-6) -> 126000000 | T27: 24
A28: 25 | B28: آباژور رومیزی | C28: 9901010026 | D28: آباژور رومیزی سفالی قهوه ای TL-C026 | E28: 45 | F28: 45 | G28: 52 | I28: 105200000 | J28: =ROUND(((100%+$M$7)*Table30[[#This Row],[قیمت (ریال)]])*(100%+$M$8),-6) -> 126000000 | T28: 25
A29: 26 | B29: آباژور رومیزی | C29: 9901010027 | D29: آباژور رومیزی سرامیکی آبی TL-C027 | E29: - | F29: - | G29: - | I29: 72000000 | J29: =ROUND(((100%+$M$7)*Table30[[#This Row],[قیمت (ریال)]])*(100%+$M$8),-6) -> 86000000 | T29: 26
A30: 27 | B30: آباژور رومیزی | C30: 9901010029 | D30: آباژور رومیزی سرامیکی آبی TL-CR029 | E30: 22 | F30: 22 | G30: 59 | I30: 72000000 | J30: =ROUND(((100%+$M$7)*Table30[[#This Row],[قیمت (ریال)]])*(100%+$M$8),-6) -> 86000000 | T30: 27
A31: 28 | B31: آباژور رومیزی | C31: 9901010030 | D31: آباژور رومیزی سنگی مشکی TL-S030 | E31: 35 | F31: 35 | G31: 39 | I31: 102900000 | J31: =ROUND(((100%+$M$7)*Table30[[#This Row],[قیمت (ریال)]])*(100%+$M$8),-6) -> 123000000 | T31: 28
A32: 29 | B32: آباژور رومیزی | C32: 9901010031 | D32: آباژور رومیزی استیل نقره ای TL-ST031 | E32: 42 | F32: 26 | G32: 67 | I32: 82600000 | J32: =ROUND(((100%+$M$7)*Table30[[#This Row],[قیمت (ریال)]])*(100%+$M$8),-6) -> 99000000 | T32: 29
A33: 30 | B33: آباژور رومیزی | C33: 9901010032 | D33: آباژور رومیزی استیل طلاییTL-ST032 | E33: 40 | F33: 40 | G33: 75 | I33: 144000000 | J33: =ROUND(((100%+$M$7)*Table30[[#This Row],[قیمت (ریال)]])*(100%+$M$8),-6) -> 173000000 | T33: 30
A34: 31 | B34: آباژور رومیزی | C34: 9901010075 | D34: آباژور رومیزی چوبی خودرنگ TL-W075 | E34: 30 | F34: 20 | G34: 60 | I34: 118700000 | J34: =ROUND(((100%+$M$7)*Table30[[#This Row],[قیمت (ریال)]])*(100%+$M$8),-6) -> 142000000 | T34: 31
A35: 32 | B35: آباژور رومیزی | C35: 9901010076 | D35: آباژور رومیزی چوبی خودرنگ TL-W076 | E35: 35 | F35: 15 | G35: 52 | I35: 118700000 | J35: =ROUND(((100%+$M$7)*Table30[[#This Row],[قیمت (ریال)]])*(100%+$M$8),-6) -> 142000000 | T35: 32
A36: 33 | B36: آباژور رومیزی | C36: 9901010077 | D36: آباژور رومیزی چوبی خودرنگ TL-W077 | E36: 35 | F36: 20 | G36: 59 | I36: 135200000 | J36: =ROUND(((100%+$M$7)*Table30[[#This Row],[قیمت (ریال)]])*(100%+$M$8),-6) -> 162000000 | T36: 33
A37: 34 | B37: آباژور رومیزی | C37: 9901010084 | D37: آباژور رومیزی چوبی خودرنگ TL-W084 | E37: 30 | F37: 20 | G37: 60 | I37: 117800000 | J37: =ROUND(((100%+$M$7)*Table30[[#This Row],[قیمت (ریال)]])*(100%+$M$8),-6) -> 141000000 | T37: 34
A38: 35 | B38: آباژور رومیزی | C38: 9901010085 | D38: آباژور رومیزی چوبی خودرنگ TL-W085 | E38: 35 | F38: 15 | G38: 52 | I38: 117800000 | J38: =ROUND(((100%+$M$7)*Table30[[#This Row],[قیمت (ریال)]])*(100%+$M$8),-6) -> 141000000 | T38: 35
A39: 36 | B39: آباژور رومیزی | C39: 9901010086 | D39: آباژور رومیزی چوبی خودرنگ TL-W086 | E39: 35 | F39: 20 | G39: 59 | I39: 135200000 | J39: =ROUND(((100%+$M$7)*Table30[[#This Row],[قیمت (ریال)]])*(100%+$M$8),-6) -> 162000000 | T39: 36
A40: 37 | B40: آباژور رومیزی | C40: 9901010087 | D40: آباژور رومیزی چوبی خودرنگ TL-W087 | E40: 30 | F40: 20 | G40: 60 | I40: 117200000 | J40: =ROUND(((100%+$M$7)*Table30[[#This Row],[قیمت (ریال)]])*(100%+$M$8),-6) -> 141000000 | T40: 37
A41: 38 | B41: آباژور رومیزی | C41: 9901010088 | D41: آباژور رومیزی چوبی خودرنگ TL-W088 | E41: 35 | F41: 15 | G41: 52 | I41: 117200000 | J41: =ROUND(((100%+$M$7)*Table30[[#This Row],[قیمت (ریال)]])*(100%+$M$8),-6) -> 141000000 | T41: 38
...

Sheet  کالای خواب حذف از لیست اصلی
A1: لیست قیمت کالای خواب حذف از تولید ( 1405/02/01)
A2: ردیف | B2: دسته بندی | C2: کد کالا | D2: شرح کالا | E2: قیمت (ریال) | F2: قیمت جدید | P2: کد کاتالوگ
A3: 1 | B3: بالش | C3: 9900120004 | D3: بالش آتریپلکس / پلوم (90%پر) | E3: 74900000 | F3: =ROUND(((100%+$K$4)*Table1085024[[#This Row],[قیمت (ریال)]])*(100%+$K$5),-6) -> 90000000 | P3: 2
A4: =A3+1 -> 2 | B4: بالش | C4: 9900120005 | D4: بالش آتریپلکس / پاکت پیلو | E4: 84200000 | F4: =ROUND(((100%+$K$4)*Table1085024[[#This Row],[قیمت (ریال)]])*(100%+$K$5),-6) -> 101000000 | J4: نرخ 1 | K4: 0.2 | P4: 3
A5: =A4+1 -> 3 | B5: بالش | C5: 9900120006 | D5: بالش آتریپلکس / بامبو | E5: 64600000 | F5: =ROUND(((100%+$K$4)*Table1085024[[#This Row],[قیمت (ریال)]])*(100%+$K$5),-6) -> 78000000 | J5: نرخ 2 | K5: 0 | P5: 4
A6: =A5+1 -> 4 | B6: بالش | C6: 9900120007 | D6: بالش آتریپلکس / آلوئه ورا | E6: 56000000 | F6: =ROUND(((100%+$K$4)*Table1085024[[#This Row],[قیمت (ریال)]])*(100%+$K$5),-6) -> 67000000 | P6: 5
A7: =A6+1 -> 5 | B7: بالش | C7: 9900120008 | D7: بالش آتریپلکس / میکرو نیدل | E7: 63600000 | F7: =ROUND(((100%+$K$4)*Table1085024[[#This Row],[قیمت (ریال)]])*(100%+$K$5),-6) -> 76000000 | P7: 6
A8: =A7+1 -> 6 | B8: بالش | C8: 9900120009 | D8: بالش آتریپلکس / آل سیزنس | E8: 63600000 | F8: =ROUND(((100%+$K$4)*Table1085024[[#This Row],[قیمت (ریال)]])*(100%+$K$5),-6) -> 76000000 | P8: 7
A9: =A8+1 -> 7 | B9: بالش | C9: 9900120010 | D9: بالش آتریپلکس / نچرال | E9: 63600000 | F9: =ROUND(((100%+$K$4)*Table1085024[[#This Row],[قیمت (ریال)]])*(100%+$K$5),-6) -> 76000000 | P9: 8
A10: =A9+1 -> 8 | B10: بالش | C10: 9900120011 | D10: بالش آتریپلکس / هایپرکلاس | E10: 73000000 | F10: =ROUND(((100%+$K$4)*Table1085024[[#This Row],[قیمت (ریال)]])*(100%+$K$5),-6) -> 88000000 | P10: 9
A11: =A10+1 -> 9 | B11: بالش | C11: 9900120012 | D11: بالش آتریپلکس / فرش کول | E11: 89900000 | F11: =ROUND(((100%+$K$4)*Table1085024[[#This Row],[قیمت (ریال)]])*(100%+$K$5),-6) -> 108000000 | P11: 10
A12: =A11+1 -> 10 | B12: بالش | C12: 9900120023 | D12: بالش مون سیلک | E12: 144000000 | F12: =ROUND(((100%+$K$4)*Table1085024[[#This Row],[قیمت (ریال)]])*(100%+$K$5),-6) -> 173000000 | P12: 11
A13: =A12+1 -> 11 | B13: بالش | C13: 9900120024 | D13: بالش توین رست | E13: 88000000 | F13: =ROUND(((100%+$K$4)*Table1085024[[#This Row],[قیمت (ریال)]])*(100%+$K$5),-6) -> 106000000 | P13: 12
A14: =A13+1 -> 12 | B14: بالش | C14: 9900120025 | D14: بالش طبی مموری ترکیبی | E14: 136800000 | F14: =ROUND(((100%+$K$4)*Table1085024[[#This Row],[قیمت (ریال)]])*(100%+$K$5),-6) -> 164000000 | P14: 13
A19: ردیف | B19: دسته بندی | C19: کد کالا | D19: شرح کالا | E19: قیمت (ریال) | F19: قیمت جدید | J19: نرخ 1 | K19: 0.2
A20: 1 | B20: سرویس روتختی | C20: 9900130005 | D20: سرویس روتختی دونفره سه تکه فریزیا / زغالی | E20: 279600000 | F20: =ROUND(((100%+$K$19)*Table10850247[[#This Row],[قیمت (ریال)]])*(100%+$K$20),-6) -> 336000000 | J20: نرخ 2 | K20: 0 | P20: 14
A21: =A20+1 -> 2 | B21: سرویس روتختی | C21: 9900130006 | D21: سرویس روتختی دونفره سه تکه فریزیا / مسی | E21: 279600000 | F21: =ROUND(((100%+$K$19)*Table10850247[[#This Row],[قیمت (ریال)]])*(100%+$K$20),-6) -> 336000000 | P21: 15
A22: =A21+1 -> 3 | B22: سرویس روتختی | C22: 9900130007 | D22: سرویس روتختی دونفره سه تکه فریزیا /آبی تیره | E22: 279600000 | F22: =ROUND(((100%+$K$19)*Table10850247[[#This Row],[قیمت (ریال)]])*(100%+$K$20),-6) -> 336000000 | P22: 16
A23: =A22+1 -> 4 | B23: سرویس روتختی | C23: 9900130008 | D23: سرویس روتختی دونفره سه تکه فریزیا / خاکستری | E23: 279600000 | F23: =ROUND(((100%+$K$19)*Table10850247[[#This Row],[قیمت (ریال)]])*(100%+$K$20),-6) -> 336000000 | P23: 17
A24: =A23+1 -> 5 | B24: سرویس روتختی | C24: 9900130009 | D24: سرویس روتختی یک نفره دو تکه فریزیا / زغالی | E24: 223000000 | F24: =ROUND(((100%+$K$19)*Table10850247[[#This Row],[قیمت (ریال)]])*(100%+$K$20),-6) -> 268000000 | P24: 18
A25: =A24+1 -> 6 | B25: سرویس روتختی | C25: 9900130010 | D25: سرویس روتختی یک نفره دو تکه فریزیا / مسی | E25: 223000000 | F25: =ROUND(((100%+$K$19)*Table10850247[[#This Row],[قیمت (ریال)]])*(100%+$K$20),-6) -> 268000000 | P25: 19
A26: =A25+1 -> 7 | B26: سرویس روتختی | C26: 9900130011 | D26: سرویس روتختی یک نفره دو تکه فریزیا / آبی تیره | E26: 223000000 | F26: =ROUND(((100%+$K$19)*Table10850247[[#This Row],[قیمت (ریال)]])*(100%+$K$20),-6) -> 268000000 | P26: 20
A27: =A26+1 -> 8 | B27: سرویس روتختی | C27: 9900130012 | D27: سرویس روتختی یک نفره دو تکه فریزیا / خاکستری | E27: 223000000 | F27: =ROUND(((100%+$K$19)*Table10850247[[#This Row],[قیمت (ریال)]])*(100%+$K$20),-6) -> 268000000 | P27: 21
A28: =A27+1 -> 9 | B28: سرویس روتختی | C28: 9900130022 | D28: سرویس روتختی دو نفره یازده تکه ماری گلد 22 | E28: 622400000 | F28: =ROUND(((100%+$K$19)*Table10850247[[#This Row],[قیمت (ریال)]])*(100%+$K$20),-6) -> 747000000 | P28: 22
A29: =A28+1 -> 10 | B29: سرویس روتختی | C29: 9900130025 | D29: سرویس روتختی و کاور کینگ ده تکه دکوماریا 25 | E29: 828800000 | F29: =ROUND(((100%+$K$19)*Table10850247[[#This Row],[قیمت (ریال)]])*(100%+$K$20),-6) -> 995000000 | P29: 23
A30: =A29+1 -> 11 | B30: سرویس روتختی | C30: 9900130030 | D30: سرویس روتختی دو نفره سه تکه کاتالیا 30 | E30: 114500000 | F30: =ROUND(((100%+$K$19)*Table10850247[[#This Row],[قیمت (ریال)]])*(100%+$K$20),-6) -> 137000000 | P30: 24
A31: =A30+1 -> 12 | B31: سرویس روتختی | C31: 9900130031 | D31: سرویس روتختی دو نفره سه تکه کاتالیا 31 | E31: 114500000 | F31: =ROUND(((100%+$K$19)*Table10850247[[#This Row],[قیمت (ریال)]])*(100%+$K$20),-6) -> 137000000 | P31: 25
A32: =A31+1 -> 13 | B32: سرویس روتختی | C32: 9900130032 | D32: سرویس روتختی دو نفره سه تکه کاتالیا 32 | E32: 114500000 | F32: =ROUND(((100%+$K$19)*Table10850247[[#This Row],[قیمت (ریال)]])*(100%+$K$20),-6) -> 137000000 | P32: 26
A33: =A32+1 -> 14 | B33: سرویس روتختی | C33: 9900130033 | D33: سرویس روتختی دو نفره سه تکه کاتالیا 33 | E33: 114500000 | F33: =ROUND(((100%+$K$19)*Table10850247[[#This Row],[قیمت (ریال)]])*(100%+$K$20),-6) -> 137000000 | P33: 27
A34: =A33+1 -> 15 | B34: سرویس روتختی | C34: 9900130034 | D34: سرویس روتختی دو نفره سه تکه کاتالیا 34 | E34: 114500000 | F34: =ROUND(((100%+$K$19)*Table10850247[[#This Row],[قیمت (ریال)]])*(100%+$K$20),-6) -> 137000000 | P34: 28
A35: =A34+1 -> 16 | B35: سرویس روتختی | C35: 9900130035 | D35: سرویس روتختی دو نفره سه تکه کاتالیا 35 | E35: 114500000 | F35: =ROUND(((100%+$K$19)*Table10850247[[#This Row],[قیمت (ریال)]])*(100%+$K$20),-6) -> 137000000 | P35: 29
A36: =A35+1 -> 17 | B36: سرویس روتختی | C36: 9900130036 | D36: سرویس روتختی دو نفره شش تکه کاتالیا پلاس 36 | E36: 223000000 | F36: =ROUND(((100%+$K$19)*Table10850247[[#This Row],[قیمت (ریال)]])*(100%+$K$20),-6) -> 268000000 | P36: 30
A37: =A36+1 -> 18 | B37: سرویس روتختی | C37: 9900130037 | D37: سرویس روتختی دو نفره شش تکه کاتالیا پلاس 37 | E37: 223000000 | F37: =ROUND(((100%+$K$19)*Table10850247[[#This Row],[قیمت (ریال)]])*(100%+$K$20),-6) -> 268000000 | P37: 31
A38: =A37+1 -> 19 | B38: سرویس روتختی | C38: 9900130038 | D38: سرویس روتختی دو نفره شش تکه کاتالیا پلاس 38 | E38: 223000000 | F38: =ROUND(((100%+$K$19)*Table10850247[[#This Row],[قیمت (ریال)]])*(100%+$K$20),-6) -> 268000000 | P38: 32
A39: =A38+1 -> 20 | B39: سرویس روتختی | C39: 9900130039 | D39: سرویس روتختی دو نفره شش تکه کاتالیا پلاس 39 | E39: 223000000 | F39: =ROUND(((100%+$K$19)*Table10850247[[#This Row],[قیمت (ریال)]])*(100%+$K$20),-6) -> 268000000 | P39: 33
A40: =A39+1 -> 21 | B40: سرویس روتختی | C40: 9900130040 | D40: سرویس روتختی دو نفره شش تکه کاتالیا پلاس 40 | E40: 223000000 | F40: =ROUND(((100%+$K$19)*Table10850247[[#This Row],[قیمت (ریال)]])*(100%+$K$20),-6) -> 268000000 | P40: 34
A41: =A40+1 -> 22 | B41: سرویس روتختی | C41: 9900130041 | D41: سرویس روتختی دو نفره شش تکه کاتالیا پلاس 41 | E41: 223000000 | F41: =ROUND(((100%+$K$19)*Table10850247[[#This Row],[قیمت (ریال)]])*(100%+$K$20),-6) -> 268000000 | P41: 35
... A50: =A49+1 -> 31 | B50: سرویس روتختی | C50: 9900130050 | D50: سرویس روتختی دو نفره لوپین / سفارشی | E50: 377500000 | F50: =ROUND(((100%+$K$19)*Table10850247[[#This Row],[قیمت (ریال)]])*(100%+$K$20),-6) -> 453000000 | P50: 44
A53: ردیف | B53: دسته بندی | C53: کد کالا | D53: شرح کالا | E53: قیمت (ریال) | F53: قیمت جدید | J53: نرخ 1 | K53: 0.2
A54: 1 | B54: سرویس ملحفه | C54: 9900140002 | D54: سرویس ملحفه دو نفره شش تکه لیاتریس | E54: 286700000 | F54: =ROUND(((100%+$K$53)*Table10850248[[#This Row],[قیمت (ریال)]])*(100%+$K$54),-6) -> 344000000 | J54: نرخ 2 | K54: 0
...

Sheet تشک حذف از تولید
B2: تشک آریل
B3: کد کالا | C3: شرح کالا | D3: ساختار | E3: ارتفاع تشک | F3: خدمات تعویض (ماه) | G3: خدمات بدون هزینه (ماه) | H3: خدمات با هزینه (ماه) | I3: قیمت (ریال) | J3: قیمت جدید
J4: قیمت جدید
B5: 9900110001 | C5: تشک 90*200 آریل | D5: فنر متصل | E5: 26 | F5: 15 | G5: 60 | H5: 120 | I5: 613100000 | J5: =ROUND(((100%+$M$6)*I5)*(100%+$M$7),-6) -> 736000000 | U5: 1
B6: 9900110002 | C6: تشک 120*200 آریل | D6: فنر متصل | E6: 26 | F6: 15 | G6: 60 | H6: 120 | I6: 830600000 | J6: =ROUND(((100%+$M$6)*I6)*(100%+$M$7),-6) -> 997000000 | L6: درصد افزایش 1 | M6: 0.2 | U6: 2
B7: 9900110003 | C7: تشک 140*200 آریل | D7: فنر متصل | E7: 26 | F7: 15 | G7: 60 | H7: 120 | I7: 958400000 | J7: =ROUND(((100%+$M$6)*I7)*(100%+$M$7),-6) -> 1150000000 | L7: درصد افزایش 2 | M7: 0 | U7: 3
B8: 9900110004 | C8: تشک 160*200 آریل | D8: فنر متصل | E8: 26 | F8: 15 | G8: 60 | H8: 120 | I8: 1093600000 | J8: =ROUND(((100%+$M$6)*I8)*(100%+$M$7),-6) -> 1312000000 | U8: 4
B9: 9900110005 | C9: تشک 180*200 آریل | D9: فنر متصل | E9: 26 | F9: 15 | G9: 60 | H9: 120 | I9: 1229200000 | J9: =ROUND(((100%+$M$6)*I9)*(100%+$M$7),-6) -> 1475000000 | U9: 5
B14: تشک پاندورا
B15: کد کالا | C15: شرح کالا | D15: ساختار | E15: ارتفاع تشک | F15: خدمات تعویض (ماه) | G15: خدمات بدون هزینه (ماه) | H15: خدمات با هزینه (ماه) | I15: قیمت (ریال) | J15: قیمت جدید
J16: قیمت جدید
B17: 9900110006 | C17: تشک 90*200 پاندورا | D17: هیبرید | E17: 29 | F17: 15 | G17: 60 | H17: 120 | I17: 729000000 | J17: =ROUND(((100%+$M$17)*I17)*(100%+$M$18),-6) -> 875000000 | L17: درصد افزایش 1 | M17: 0.2
B18: 9900110007 | C18: تشک 120*200 پاندورا | D18: هیبرید | E18: 29 | F18: 15 | G18: 60 | H18: 120 | I18: 986000000 | J18: =ROUND(((100%+$M$17)*I18)*(100%+$M$18),-6) -> 1183000000 | L18: درصد افزایش 2 | M18: 0
B19: 9900110008 | C19: تشک 140*200 پاندورا | D19: هیبرید | E19: 29 | F19: 15 | G19: 60 | H19: 120 | I19: 1136000000 | J19: =ROUND(((100%+$M$17)*I19)*(100%+$M$18),-6) -> 1363000000
B20: 9900110009 | C20: تشک 160*200 پاندورا | D20: هیبرید | E20: 29 | F20: 15 | G20: 60 | H20: 120 | I20: 1301000000 | J20: =ROUND(((100%+$M$17)*I20)*(100%+$M$18),-6) -> 1561000000
B21: 9900110010 | C21: تشک 180*200 پاندورا | D21: هیبرید | E21: 29 | F21: 15 | G21: 60 | H21: 120 | I21: 1458000000 | J21: =ROUND(((100%+$M$17)*I21)*(100%+$M$18),-6) -> 1750000000

Sheet کاتالوگ تشک
R1: تاریخ لیست قیمت | S1: 1405/02/23
F22: لیست قیمت تشک حذف از تولید
M26: (1405/02/23)
E59: تشک آریل | N59: =$S$1 -> 1405/02/23
D60: ردیف | E60: کد کالا | G60: شرح | J60: ساختار | K60: ارتفاع تشک | L60: خدمات تعویض (ماه) | M60: خدمات بدون هزینه (ماه) | N60: خدمات با هزینه (ماه) | O60: قیمت (ریال)
D62: 1 | E62: =INDEX('تشک حذف از تولید'!B:B,MATCH(P62,'تشک حذف از تولید'!U:U,0)) -> 9900110001 | G62: =INDEX('تشک حذف از تولید'!C:C,MATCH(P62,'تشک حذف از تولید'!U:U,0)) -> تشک 90*200 آریل | J62: =INDEX('تشک حذف از تولید'!D:D,MATCH(P62,'تشک حذف از تولید'!U:U,0)) -> فنر متصل | K62: =INDEX('تشک حذف از تولید'!E:E,MATCH(P62,'تشک حذف از تولید'!U:U,0)) -> 26 | L62: =INDEX('تشک حذف از تولید'!F:F,MATCH(P62,'تشک حذف از تولید'!U:U,0)) -> 15 | M62: =INDEX('تشک حذف از تولید'!G:G,MATCH(P62,'تشک حذف از تولید'!U:U,0)) -> 60 | N62: =INDEX('تشک حذف از تولید'!H:H,MATCH(P62,'تشک حذف از تولید'!U:U,0)) -> 120 | O62: =INDEX('تشک حذف از تولید'!J:J,MATCH(P62,'تشک حذف از تولید'!U:U,0)) -> 736000000 | P62: 1
D63: 2 | E63: =INDEX('تشک حذف از تولید'!B:B,MATCH(P63,'تشک حذف از تولید'!U:U,0)) -> 9900110002 | G63: =INDEX('تشک حذف از تولید'!C:C,MATCH(P63,'تشک حذف از تولید'!U:U,0)) -> تشک 120*200 آریل | J63: =INDEX('تشک حذف از تولید'!D:D,MATCH(P63,'تشک حذف از تولید'!U:U,0)) -> فنر متصل | K63: =INDEX('تشک حذف از تولید'!E:E,MATCH(P63,'تشک حذف از تولید'!U:U,0)) -> 26 | L63: =INDEX('تشک حذف از تولید'!F:F,MATCH(P63,'تشک حذف از تولید'!U:U,0)) -> 15 | M63: =INDEX('تشک حذف از تولید'!G:G,MATCH(P63,'تشک حذف از تولید'!U:U,0)) -> 60 | N63: =INDEX('تشک حذف از تولید'!H:H,MATCH(P63,'تشک حذف از تولید'!U:U,0)) -> 120 | O63: =INDEX('تشک حذف از تولید'!J:J,MATCH(P63,'تشک حذف از تولید'!U:U,0)) -> 997000000 | P63: 2
D64: 3 | E64: =INDEX('تشک حذف از تولید'!B:B,MATCH(P64,'تشک حذف از تولید'!U:U,0)) -> 9900110003 | G64: =INDEX('تشک حذف از تولید'!C:C,MATCH(P64,'تشک حذف از تولید'!U:U,0)) -> تشک 140*200 آریل | J64: =INDEX('تشک حذف از تولید'!D:D,MATCH(P64,'تشک حذف از تولید'!U:U,0)) -> فنر متصل | K64: =INDEX('تشک حذف از تولید'!E:E,MATCH(P64,'تشک حذف از تولید'!U:U,0)) -> 26 | L64: =INDEX('تشک حذف از تولید'!F:F,MATCH(P64,'تشک حذف از تولید'!U:U,0)) -> 15 | M64: =INDEX('تشک حذف از تولید'!G:G,MATCH(P64,'تشک حذف از تولید'!U:U,0)) -> 60 | N64: =INDEX('تشک حذف از تولید'!H:H,MATCH(P64,'تشک حذف از تولید'!U:U,0)) -> 120 | O64: =INDEX('تشک حذف از تولید'!J:J,MATCH(P64,'تشک حذف از تولید'!U:U,0)) -> 1150000000 | P64: 3
D65: 4 | E65: =INDEX('تشک حذف از تولید'!B:B,MATCH(P65,'تشک حذف از تولید'!U:U,0)) -> 9900110004 | G65: =INDEX('تشک حذف از تولید'!C:C,MATCH(P65,'تشک حذف از تولید'!U:U,0)) -> تشک 160*200 آریل | J65: =INDEX('تشک حذف از تولید'!D:D,MATCH(P65,'تشک حذف از تولید'!U:U,0)) -> فنر متصل | K65: =INDEX('تشک حذف از تولید'!E:E,MATCH(P65,'تشک حذف از تولید'!U:U,0)) -> 26 | L65: =INDEX('تشک حذف از تولید'!F:F,MATCH(P65,'تشک حذف از تولید'!U:U,0)) -> 15 | M65: =INDEX('تشک حذف از تولید'!G:G,MATCH(P65,'تشک حذف از تولید'!U:U,0)) -> 60 | N65: =INDEX('تشک حذف از تولید'!H:H,MATCH(P65,'تشک حذف از تولید'!U:U,0)) -> 120 | O65: =INDEX('تشک حذف از تولید'!J:J,MATCH(P65,'تشک حذف از تولید'!U:U,0)) -> 1312000000 | P65: 4
D66: 5 | E66: =INDEX('تشک حذف از تولید'!B:B,MATCH(P66,'تشک حذف از تولید'!U:U,0)) -> 9900110005 | G66: =INDEX('تشک حذف از تولید'!C:C,MATCH(P66,'تشک حذف از تولید'!U:U,0)) -> تشک 180*200 آریل | J66: =INDEX('تشک حذف از تولید'!D:D,MATCH(P66,'تشک حذف از تولید'!U:U,0)) -> فنر متصل | K66: =INDEX('تشک حذف از تولید'!E:E,MATCH(P66,'تشک حذف از تولید'!U:U,0)) -> 26 | L66: =INDEX('تشک حذف از تولید'!F:F,MATCH(P66,'تشک حذف از تولید'!U:U,0)) -> 15 | M66: =INDEX('تشک حذف از تولید'!G:G,MATCH(P66,'تشک حذف از تولید'!U:U,0)) -> 60 | N66: =INDEX('تشک حذف از تولید'!H:H,MATCH(P66,'تشک حذف از تولید'!U:U,0)) -> 120 | O66: =INDEX('تشک حذف از تولید'!J:J,MATCH(P66,'تشک حذف از تولید'!U:U,0)) -> 1475000000 | P66: 5

Sheet کاتالوگ اکسسوری
M1: تاریخ لیست قیمت | N1: 1405/02/23
C19: لیست قیمت اکسسوری حذف از تولید
H22: ="( " &$N$1&" )" -> ( 1405/02/23 )
D41: فهرست
D42: دسته محصولات | J42: صفحه
D44: آباژور رومیزی | J44: 3-6
D46: آباژور ایستاده | J46: 7
D48: لوستر | J48: 8
D50: آویز | J50: 9
D52: دیوارکوب | J52: 10
D54: مبلمان فضای باز | J54: 10
D56: میز | J56: 11
D58: شال مبل | J58: 12
D60: رانر | J60: 13-14
D62: دستمال سفره و زیربشقابی | J62: 14
D64: کوسن | J64: 15-16
D66: ظرف پذیرایی | J66: 17-19
D68: گل مصنوعی | J68: 20
D70: گلدان | J70: 21-23
D72: شمع دکوراتیو | J72: 24
D74: شمعدان | J74: 25-26
D76: زیر سیگاری | J76: 26
D78: عطر خانگی | J78: 26
D80: عودسوز | J80: 27
D82: فهرست
D83: دسته محصولات | J83: صفحه
D85: تابلو | J85: 27
D87: ساعت | J87: 28
D89: آینه | J89: 28
D91: دکوراتیو | J91: 29
D93: جالباسی | J93: 30
D95: استند روزنامه | J95: 30
D97: فرش | J97: 31-34
D99: نگهدارنده کتاب | J99: 35
D101: آشیانه حیوانات | J101: 35
D103: کارد و چنگال | J103: 36
D126: آّباژور رومیزی | J126: =$N$1 -> 1405/02/23
D127: ردیف | E127: کد کالا | F127: شرح کالا | G127: طول (cm) | H127: عرض (cm) | I127: ارتفاع (cm) | J127: قیمت (ریال)
D128: 1 | E128: =INDEX('اکسسوری حذف از لیست اصلی'!C:C,MATCH(K128,'اکسسوری حذف از لیست اصلی'!T:T,0)) -> 9901010001 | F128: =INDEX('اکسسوری حذف از لیست اصلی'!D:D,MATCH(K128,'اکسسوری حذف از لیست اصلی'!T:T,0)) -> آباژور رومیزی چوبی طوسی TL-W001 | G128: =INDEX('اکسسوری حذف از لیست اصلی'!E:E,MATCH(K128,'اکسسوری حذف از لیست اصلی'!T:T,0)) -> 43 | H128: =INDEX('اکسسوری حذف از لیست اصلی'!F:F,MATCH(K128,'اکسسوری حذف از لیست اصلی'!T:T,0)) -> 43 | I128: =INDEX('اکسسوری حذف از لیست اصلی'!G:G,MATCH(K128,'اکسسوری حذف از لیست اصلی'!T:T,0)) -> 69 | J128: =INDEX('اکسسوری حذف از لیست اصلی'!J:J,MATCH(K128,'اکسسوری حذف از لیست اصلی'!T:T,0)) -> 124000000 | K128: 1
D129: 2 | E129: =INDEX('اکسسوری حذف از لیست اصلی'!C:C,MATCH(K129,'اکسسوری حذف از لیست اصلی'!T:T,0)) -> 9901010002 | F129: =INDEX('اکسسوری حذف از لیست اصلی'!D:D,MATCH(K129,'اکسسوری حذف از لیست اصلی'!T:T,0)) -> آباژور رومیزی چوبی مشکی طلایی TL-W002 | G129: =INDEX('اکسسوری حذف از لیست اصلی'!E:E,MATCH(K129,'اکسسوری حذف از لیست اصلی'!T:T,0)) -> 43 | H129: =INDEX('اکسسوری حذف از لیست اصلی'!F:F,MATCH(K129,'اکسسوری حذف از لیست اصلی'!T:T,0)) -> 43 | I129: =INDEX('اکسسوری حذف از لیست اصلی'!G:G,MATCH(K129,'اکسسوری حذف از لیست اصلی'!T:T,0)) -> 70 | J129: =INDEX('اکسسوری حذف از لیست اصلی'!J:J,MATCH(K129,'اکسسوری حذف از لیست اصلی'!T:T,0)) -> 124000000 | K129: 2
...
